Workbook

Sheet Warehouse Pick
A1: Vendor Item No. | B1: Action Performed | C1: Warehouse Quantity | D1: Warehouse Unit Of Measure | E1: Item No. | F1: Description | G1: Action Type | H1: Quantity | I1: Salvage Date | J1: Salvage Period | K1: Qty. to Handle | L1: Qty. Handled | M1: Qty. Outstanding | N1: Due Date | O1: Unit of Measure Code | P1: Qty. per Unit of Measure | Q1: Destination Type | R1: Destination No. | S1: Serial No. | T1: Status | U1: Destinantion Description | V1: Bin Code | W1: Lot No. | X1: Skip Line | Y1: Internal Pallet Barcode

Sheet Calc
A1: {=IF((HLOOKUP("Serial No.",'Warehouse Pick'!$A$1:$ZZ$10000,ROW(2:2),FALSE))=0," ",HLOOKUP("Serial No.",'Warehouse Pick'!$A$1:$ZZ$10000,ROW(2:2),FALSE))}
A2: {=IF((HLOOKUP("Serial No.",'Warehouse Pick'!$A$1:$ZZ$10000,ROW(3:3),FALSE))=0," ",HLOOKUP("Serial No.",'Warehouse Pick'!$A$1:$ZZ$10000,ROW(3:3),FALSE))} -> N125233201
A3: {=IF((HLOOKUP("Serial No.",'Warehouse Pick'!$A$1:$ZZ$10000,ROW(4:4),FALSE))=0," ",HLOOKUP("Serial No.",'Warehouse Pick'!$A$1:$ZZ$10000,ROW(4:4),FALSE))} -> N125233202
A4: {=IF((HLOOKUP("Serial No.",'Warehouse Pick'!$A$1:$ZZ$10000,ROW(5:5),FALSE))=0," ",HLOOKUP("Serial No.",'Warehouse Pick'!$A$1:$ZZ$10000,ROW(5:5),FALSE))} -> N125233203
A5: {=IF((HLOOKUP("Serial No.",'Warehouse Pick'!$A$1:$ZZ$10000,ROW(6:6),FALSE))=0," ",HLOOKUP("Serial No.",'Warehouse Pick'!$A$1:$ZZ$10000,ROW(6:6),FALSE))} -> N125233204
A6: {=IF((HLOOKUP("Serial No.",'Warehouse Pick'!$A$1:$ZZ$10000,ROW(7:7),FALSE))=0," ",HLOOKUP("Serial No.",'Warehouse Pick'!$A$1:$ZZ$10000,ROW(7:7),FALSE))} -> N125233205
A7: {=IF((HLOOKUP("Serial No.",'Warehouse Pick'!$A$1:$ZZ$10000,ROW(8:8),FALSE))=0," ",HLOOKUP("Serial No.",'Warehouse Pick'!$A$1:$ZZ$10000,ROW(8:8),FALSE))} -> N125233207
A8: {=IF((HLOOKUP("Serial No.",'Warehouse Pick'!$A$1:$ZZ$10000,ROW(9:9),FALSE))=0," ",HLOOKUP("Serial No.",'Warehouse Pick'!$A$1:$ZZ$10000,ROW(9:9),FALSE))} -> N125233208
A9: {=IF((HLOOKUP("Serial No.",'Warehouse Pick'!$A$1:$ZZ$10000,ROW(10:10),FALSE))=0," ",HLOOKUP("Serial No.",'Warehouse Pick'!$A$1:$ZZ$10000,ROW(10:10),FALSE))} -> N125233209
A10: {=IF((HLOOKUP("Serial No.",'Warehouse Pick'!$A$1:$ZZ$10000,ROW(11:11),FALSE))=0," ",HLOOKUP("Serial No.",'Warehouse Pick'!$A$1:$ZZ$10000,ROW(11:11),FALSE))} -> N125233210
A11: {=IF((HLOOKUP("Serial No.",'Warehouse Pick'!$A$1:$ZZ$10000,ROW(12:12),FALSE))=0," ",HLOOKUP("Serial No.",'Warehouse Pick'!$A$1:$ZZ$10000,ROW(12:12),FALSE))} -> N125233211
A12: {=IF((HLOOKUP("Serial No.",'Warehouse Pick'!$A$1:$ZZ$10000,ROW(13:13),FALSE))=0," ",HLOOKUP("Serial No.",'Warehouse Pick'!$A$1:$ZZ$10000,ROW(13:13),FALSE))} -> N125233212
A13: {=IF((HLOOKUP("Serial No.",'Warehouse Pick'!$A$1:$ZZ$10000,ROW(14:14),FALSE))=0," ",HLOOKUP("Serial No.",'Warehouse Pick'!$A$1:$ZZ$10000,ROW(14:14),FALSE))} -> N125233213
A14: {=IF((HLOOKUP("Serial No.",'Warehouse Pick'!$A$1:$ZZ$10000,ROW(15:15),FALSE))=0," ",HLOOKUP("Serial No.",'Warehouse Pick'!$A$1:$ZZ$10000,ROW(15:15),FALSE))} -> N125233214
A15: {=IF((HLOOKUP("Serial No.",'Warehouse Pick'!$A$1:$ZZ$10000,ROW(16:16),FALSE))=0," ",HLOOKUP("Serial No.",'Warehouse Pick'!$A$1:$ZZ$10000,ROW(16:16),FALSE))} -> N125233215
A16: {=IF((HLOOKUP("Serial No.",'Warehouse Pick'!$A$1:$ZZ$10000,ROW(17:17),FALSE))=0," ",HLOOKUP("Serial No.",'Warehouse Pick'!$A$1:$ZZ$10000,ROW(17:17),FALSE))} -> N125233216
A17: {=IF((HLOOKUP("Serial No.",'Warehouse Pick'!$A$1:$ZZ$10000,ROW(18:18),FALSE))=0," ",HLOOKUP("Serial No.",'Warehouse Pick'!$A$1:$ZZ$10000,ROW(18:18),FALSE))} -> N125233217
A18: {=IF((HLOOKUP("Serial No.",'Warehouse Pick'!$A$1:$ZZ$10000,ROW(19:19),FALSE))=0," ",HLOOKUP("Serial No.",'Warehouse Pick'!$A$1:$ZZ$10000,ROW(19:19),FALSE))} -> N125233218
A19: {=IF((HLOOKUP("Serial No.",'Warehouse Pick'!$A$1:$ZZ$10000,ROW(20:20),FALSE))=0," ",HLOOKUP("Serial No.",'Warehouse Pick'!$A$1:$ZZ$10000,ROW(20:20),FALSE))} -> N125233219
A20: {=IF((HLOOKUP("Serial No.",'Warehouse Pick'!$A$1:$ZZ$10000,ROW(21:21),FALSE))=0," ",HLOOKUP("Serial No.",'Warehouse Pick'!$A$1:$ZZ$10000,ROW(21:21),FALSE))} -> N125233220
A21: {=IF((HLOOKUP("Serial No.",'Warehouse Pick'!$A$1:$ZZ$10000,ROW(22:22),FALSE))=0," ",HLOOKUP("Serial No.",'Warehouse Pick'!$A$1:$ZZ$10000,ROW(22:22),FALSE))} -> N125233221
A22: {=IF((HLOOKUP("Serial No.",'Warehouse Pick'!$A$1:$ZZ$10000,ROW(23:23),FALSE))=0," ",HLOOKUP("Serial No.",'Warehouse Pick'!$A$1:$ZZ$10000,ROW(23:23),FALSE))} -> N125233222
A23: {=IF((HLOOKUP("Serial No.",'Warehouse Pick'!$A$1:$ZZ$10000,ROW(24:24),FALSE))=0," ",HLOOKUP("Serial No.",'Warehouse Pick'!$A$1:$ZZ$10000,ROW(24:24),FALSE))} -> N125233223
A24: {=IF((HLOOKUP("Serial No.",'Warehouse Pick'!$A$1:$ZZ$10000,ROW(25:25),FALSE))=0," ",HLOOKUP("Serial No.",'Warehouse Pick'!$A$1:$ZZ$10000,ROW(25:25),FALSE))} -> N125233224
A25: {=IF((HLOOKUP("Serial No.",'Warehouse Pick'!$A$1:$ZZ$10000,ROW(26:26),FALSE))=0," ",HLOOKUP("Serial No.",'Warehouse Pick'!$A$1:$ZZ$10000,ROW(26:26),FALSE))} -> N125233225
A26: {=IF((HLOOKUP("Serial No.",'Warehouse Pick'!$A$1:$ZZ$10000,ROW(27:27),FALSE))=0," ",HLOOKUP("Serial No.",'Warehouse Pick'!$A$1:$ZZ$10000,ROW(27:27),FALSE))} -> N125233226
A27: {=IF((HLOOKUP("Serial No.",'Warehouse Pick'!$A$1:$ZZ$10000,ROW(28:28),FALSE))=0," ",HLOOKUP("Serial No.",'Warehouse Pick'!$A$1:$ZZ$10000,ROW(28:28),FALSE))} -> N125233227
A28: {=IF((HLOOKUP("Serial No.",'Warehouse Pick'!$A$1:$ZZ$10000,ROW(29:29),FALSE))=0," ",HLOOKUP("Serial No.",'Warehouse Pick'!$A$1:$ZZ$10000,ROW(29:29),FALSE))} -> N125233228
A29: {=IF((HLOOKUP("Serial No.",'Warehouse Pick'!$A$1:$ZZ$10000,ROW(30:30),FALSE))=0," ",HLOOKUP("Serial No.",'Warehouse Pick'!$A$1:$ZZ$10000,ROW(30:30),FALSE))} -> N125233229
A30: {=IF((HLOOKUP("Serial No.",'Warehouse Pick'!$A$1:$ZZ$10000,ROW(31:31),FALSE))=0," ",HLOOKUP("Serial No.",'Warehouse Pick'!$A$1:$ZZ$10000,ROW(31:31),FALSE))} -> N125233230
A31: {=IF((HLOOKUP("Serial No.",'Warehouse Pick'!$A$1:$ZZ$10000,ROW(32:32),FALSE))=0," ",HLOOKUP("Serial No.",'Warehouse Pick'!$A$1:$ZZ$10000,ROW(32:32),FALSE))} -> N125233231
A32: {=IF((HLOOKUP("Serial No.",'Warehouse Pick'!$A$1:$ZZ$10000,ROW(33:33),FALSE))=0," ",HLOOKUP("Serial No.",'Warehouse Pick'!$A$1:$ZZ$10000,ROW(33:33),FALSE))} -> N125233232
A33: {=IF((HLOOKUP("Serial No.",'Warehouse Pick'!$A$1:$ZZ$10000,ROW(34:34),FALSE))=0," ",HLOOKUP("Serial No.",'Warehouse Pick'!$A$1:$ZZ$10000,ROW(34:34),FALSE))} -> N125233233
A34: {=IF((HLOOKUP("Serial No.",'Warehouse Pick'!$A$1:$ZZ$10000,ROW(35:35),FALSE))=0," ",HLOOKUP("Serial No.",'Warehouse Pick'!$A$1:$ZZ$10000,ROW(35:35),FALSE))} -> N125233234
A35: {=IF((HLOOKUP("Serial No.",'Warehouse Pick'!$A$1:$ZZ$10000,ROW(36:36),FALSE))=0," ",HLOOKUP("Serial No.",'Warehouse Pick'!$A$1:$ZZ$10000,ROW(36:36),FALSE))} -> N125233235
A36: {=IF((HLOOKUP("Serial No.",'Warehouse Pick'!$A$1:$ZZ$10000,ROW(37:37),FALSE))=0," ",HLOOKUP("Serial No.",'Warehouse Pick'!$A$1:$ZZ$10000,ROW(37:37),FALSE))} -> N125233236
A37: {=IF((HLOOKUP("Serial No.",'Warehouse Pick'!$A$1:$ZZ$10000,ROW(38:38),FALSE))=0," ",HLOOKUP("Serial No.",'Warehouse Pick'!$A$1:$ZZ$10000,ROW(38:38),FALSE))} -> N125233237
A38: {=IF((HLOOKUP("Serial No.",'Warehouse Pick'!$A$1:$ZZ$10000,ROW(39:39),FALSE))=0," ",HLOOKUP("Serial No.",'Warehouse Pick'!$A$1:$ZZ$10000,ROW(39:39),FALSE))} -> N125233238
A39: {=IF((HLOOKUP("Serial No.",'Warehouse Pick'!$A$1:$ZZ$10000,ROW(40:40),FALSE))=0," ",HLOOKUP("Serial No.",'Warehouse Pick'!$A$1:$ZZ$10000,ROW(40:40),FALSE))} -> N125233239
A40: {=IF((HLOOKUP("Serial No.",'Warehouse Pick'!$A$1:$ZZ$10000,ROW(41:41),FALSE))=0," ",HLOOKUP("Serial No.",'Warehouse Pick'!$A$1:$ZZ$10000,ROW(41:41),FALSE))} -> N125233240
...

Sheet Scan
B1: Serial No. Check
B3: ="("&COUNTA(B5:B10000)-1&")" -> (76) | D3: ="("&COUNTA(D5:D1000)&")" -> (0) | E3: ="("&COUNTA(E5:E1000)&")" -> (0) | F3: ="("&COUNTA(F5:F1000)&")" -> (0) | G3: ="("&COUNTA(G5:G1000)&")" -> (0) | H3: ="("&COUNTA(H5:H1000)&")" -> (0) | I3: ="("&COUNTA(I5:I1000)&")" -> (0) | J3: ="("&COUNTA(J5:J1000)&")" -> (0) | K3: ="("&COUNTA(K5:K1000)&")" -> (0) | ... M3: ="("&COUNTA(M5:M1000)&")" -> (0)
B4: Pumpen im Pick: | D4: Palette 1 | E4: Palette 2 | F4: Palette 3 | G4: Palette 4 | H4: Palette 5 | I4: Palette 6 | J4: Palette 7 | K4: Palette 8 | L4: Palette 9 | M4: Palette 10
B5: {=_xlfn.UNIQUE(Calc!A1:A9999)}

Sheet Customer
A1: pallet overview for pump serial numbers
A3: amount | B3: =Scan!D3 -> (0) | C3: =Scan!E3 -> (0) | D3: =Scan!F3 -> (0) | E3: =Scan!G3 -> (0) | F3: =Scan!H3 -> (0) | G3: =Scan!I3 -> (0) | H3: =Scan!J3 -> (0) | I3: =Scan!K3 -> (0) | ... K3: =Scan!M3 -> (0)
A4: pallet | B4: =Scan!D4 -> Palette 1 | C4: =Scan!E4 -> Palette 2 | D4: =Scan!F4 -> Palette 3 | E4: =Scan!G4 -> Palette 4 | F4: =Scan!H4 -> Palette 5 | G4: =Scan!I4 -> Palette 6 | H4: =Scan!J4 -> Palette 7 | I4: =Scan!K4 -> Palette 8 | ... K4: =Scan!M4 -> Palette 10
A5: 1 | B5: =Scan!D5 -> 0 | C5: =Scan!E5 -> 0 | D5: =Scan!F5 -> 0 | E5: =Scan!G5 -> 0 | F5: =Scan!H5 -> 0 | G5: =Scan!I5 -> 0 | H5: =Scan!J5 -> 0 | I5: =Scan!K5 -> 0 | ... K5: =Scan!M5 -> 0
A6: 2 | B6: =Scan!D6 -> 0 | C6: =Scan!E6 -> 0 | D6: =Scan!F6 -> 0 | E6: =Scan!G6 -> 0 | F6: =Scan!H6 -> 0 | G6: =Scan!I6 -> 0 | H6: =Scan!J6 -> 0 | I6: =Scan!K6 -> 0 | ... K6: =Scan!M6 -> 0
A7: 3 | B7: =Scan!D7 -> 0 | C7: =Scan!E7 -> 0 | D7: =Scan!F7 -> 0 | E7: =Scan!G7 -> 0 | F7: =Scan!H7 -> 0 | G7: =Scan!I7 -> 0 | H7: =Scan!J7 -> 0 | I7: =Scan!K7 -> 0 | ... K7: =Scan!M7 -> 0
A8: 4 | B8: =Scan!D8 -> 0 | C8: =Scan!E8 -> 0 | D8: =Scan!F8 -> 0 | E8: =Scan!G8 -> 0 | F8: =Scan!H8 -> 0 | G8: =Scan!I8 -> 0 | H8: =Scan!J8 -> 0 | I8: =Scan!K8 -> 0 | ... K8: =Scan!M8 -> 0
A9: 5 | B9: =Scan!D9 -> 0 | C9: =Scan!E9 -> 0 | D9: =Scan!F9 -> 0 | E9: =Scan!G9 -> 0 | F9: =Scan!H9 -> 0 | G9: =Scan!I9 -> 0 | H9: =Scan!J9 -> 0 | I9: =Scan!K9 -> 0 | ... K9: =Scan!M9 -> 0
A10: 6 | B10: =Scan!D10 -> 0 | C10: =Scan!E10 -> 0 | D10: =Scan!F10 -> 0 | E10: =Scan!G10 -> 0 | F10: =Scan!H10 -> 0 | G10: =Scan!I10 -> 0 | H10: =Scan!J10 -> 0 | I10: =Scan!K10 -> 0 | ... K10: =Scan!M10 -> 0
A11: 7 | B11: =Scan!D11 -> 0 | C11: =Scan!E11 -> 0 | D11: =Scan!F11 -> 0 | E11: =Scan!G11 -> 0 | F11: =Scan!H11 -> 0 | G11: =Scan!I11 -> 0 | H11: =Scan!J11 -> 0 | I11: =Scan!K11 -> 0 | ... K11: =Scan!M11 -> 0
A12: 8 | B12: =Scan!D12 -> 0 | C12: =Scan!E12 -> 0 | D12: =Scan!F12 -> 0 | E12: =Scan!G12 -> 0 | F12: =Scan!H12 -> 0 | G12: =Scan!I12 -> 0 | H12: =Scan!J12 -> 0 | I12: =Scan!K12 -> 0 | ... K12: =Scan!M12 -> 0
A13: 9 | B13: =Scan!D13 -> 0 | C13: =Scan!E13 -> 0 | D13: =Scan!F13 -> 0 | E13: =Scan!G13 -> 0 | F13: =Scan!H13 -> 0 | G13: =Scan!I13 -> 0 | H13: =Scan!J13 -> 0 | I13: =Scan!K13 -> 0 | ... K13: =Scan!M13 -> 0
A14: 10 | B14: =Scan!D14 -> 0 | C14: =Scan!E14 -> 0 | D14: =Scan!F14 -> 0 | E14: =Scan!G14 -> 0 | F14: =Scan!H14 -> 0 | G14: =Scan!I14 -> 0 | H14: =Scan!J14 -> 0 | I14: =Scan!K14 -> 0 | ... K14: =Scan!M14 -> 0
A15: 11 | B15: =Scan!D15 -> 0 | C15: =Scan!E15 -> 0 | D15: =Scan!F15 -> 0 | E15: =Scan!G15 -> 0 | F15: =Scan!H15 -> 0 | G15: =Scan!I15 -> 0 | H15: =Scan!J15 -> 0 | I15: =Scan!K15 -> 0 | ... K15: =Scan!M15 -> 0
A16: 12 | B16: =Scan!D16 -> 0 | C16: =Scan!E16 -> 0 | D16: =Scan!F16 -> 0 | E16: =Scan!G16 -> 0 | F16: =Scan!H16 -> 0 | G16: =Scan!I16 -> 0 | H16: =Scan!J16 -> 0 | I16: =Scan!K16 -> 0 | ... K16: =Scan!M16 -> 0
... A104: 100 | B104: =Scan!D104 -> 0 | C104: =Scan!E104 -> 0 | D104: =Scan!F104 -> 0 | E104: =Scan!G104 -> 0 | F104: =Scan!H104 -> 0 | G104: =Scan!I104 -> 0 | H104: =Scan!J104 -> 0 | I104: =Scan!K104 -> 0 | ... K104: =Scan!M104 -> 0
